Workbook
Name a: #REF!
Name A: 'DPK Import'!$C:$C
Name AA: #REF!
Name AA: #REF!
Name AA: #REF!
Name AA: #REF!
Name AA: #REF!
Name AA: #REF!
Name AA: #REF!
Name AA: #REF!
Name AA: #REF!
Name AA: #REF!
Name AA: #REF!
Name AA: #REF!
Name AA: #REF!
Name AA: #REF!
Name AA: #REF!
Name AA: #REF!
Name AA: #REF!
Name AA: #REF!
Name AGO: #REF!
Name AGO: #REF!
Name AGO: #REF!
Name AGO: #REF!
Name AGO: #REF!
Name AGO: #REF!
Name AGO: #REF!
Name AGO: #REF!
Name AGO: #REF!
Name AGO: #REF!
Name AGO: #REF!
Name AGO: #REF!
Name AGO: #REF!
Name AGO: #REF!
Name AGO: #REF!
Name AGO: #REF!
Name AGO: #REF!
Name AGO: #REF!
Name AP_END: '[1]Client Data'!$D$6
Name b: #REF!
Name b: #REF!
Name b: #REF!
Name b: #REF!
Name b: #REF!
Name b: #REF!
Name b: #REF!
Name b: #REF!
Name b: #REF!
Name b: #REF!
Name b: #REF!
Name b: #REF!
Name b: #REF!
Name b: #REF!
Name bsnotes: #REF!
Name D: #REF!
Name Data: [2]Sheet1!$C$5:$V$185
Name DDD: #REF!
Name DDD: #REF!
Name DDD: #REF!
Name DDD: #REF!

Sheet Exchange Rates Feb 23
C3: 15 March - 14 April 2023
C4: Importer | D4: Vessel Name | E4: Last dates of discharge | F4: Deemed Exchange Rate Date | G4: Bank 1 | H4: Bank 2 | I4: Bank 3 | J4: Average Rate for Commercial Banks | K4: CBK | L4: Average | M4: Product | N4: Terminal | O4: NoR | P4: 43733 | R4: 43762 | T4: 43795
A5: 1 | C5: TEXAS ENERGY | D5: MT Sealegend | E5: 44971 | F5: 44971 | G5: 134.4288 | H5: 131.43 | I5: 133.5 | J5: =AVERAGE(G5:I5) -> 133.1196 | L5: =AVERAGE(J5:K5) -> 133.1196 | M5: AGO K02/2023 | N5: KOSF/KPRL
A6: 2 | C6: ORYXENERGIES | D6: MT STI LOTUS | E6: 44988 | F6: 44988 | G6: 137.0016 | H6: 136.99 | I6: 137.75 | J6: =AVERAGE(G6:I6) -> 137.2472 | L6: =AVERAGE(J6:K6) -> 137.2472 | M6: AGO K03/2023 | N6: KOSF/KPRL
A7: 3 | C7: E3 ENERGY | D7: MT Serengeti | E7: 44983 | F7: 44984 | G7: 136.0368 | H7: 133.95 | I7: 136.9 | J7: =AVERAGE(G7:I7) -> 135.62893 | L7: =AVERAGE(J7:K7) -> 135.62893 | M7: AGO V02/2023 | N7: KOSF | O7: 43808.662 | P7: AGO | Q7: V08/2019
A8: 4 | C8: E3 ENERGY | D8: MT Serengeti | E8: 44983 | F8: 44984 | G8: 136.0368 | H8: 133.95 | I8: 136.9 | J8: =AVERAGE(G8:I8) -> 135.62893 | L8: =AVERAGE(J8:K8) -> 135.62893 | M8: AGO V02/2023 | N8: VTTI
A9: 5 | C9: E3 ENERGY | D9: MT Nakhal Silver | E9: 44975 | F9: 44977 | G9: 134.7504 | H9: 132.05 | I9: 134.9 | J9: =AVERAGE(G9:I9) -> 133.90013 | L9: =AVERAGE(J9:K9) -> 133.90013 | M9: JETA-1 K03/2023 | N9: KOSF/KPRL
A10: 6 | C10: ORYXENERGIES | D10: MT Hafnia Lupus | E10: 44994 | F10: 44994 | G10: 139.2328 | H10: 138.02 | I10: 138.95 | J10: =AVERAGE(G10:I10) -> 138.73427 | L10: =AVERAGE(J10:K10) -> 138.73427 | M10: JETA-1K04/2023 | N10: KOSF
A11: 7 | C11: GULF ENERGY | D11: Mt Front Vega | E11: 44978 | F11: 44978 | G11: 135.1792 | H11: 132.56 | I11: 134.9 | J11: =AVERAGE(G11:I11) -> 134.21307 | L11: =AVERAGE(J11:K11) -> 134.21307 | M11: PMS K03/2023 | N11: KOSF/KPRL
A12: 8 | C12: GULF ENERGY | D12: MT Clearocean Mesquite - TOP UP | E12: 44980 | F12: 44980 | G12: 135.608 | H12: 133.23 | I12: 135.4 | J12: =AVERAGE(G12:I12) -> 134.746 | L12: =AVERAGE(J12:K12) -> 134.746 | M12: PMS K03/2023 | N12: KOSF
A13: 9 | C13: E3 ENERGY | D13: MT Sanmar Sangeet | E13: 44993 | F13: 44993 | G13: 137.8592 | H13: 137.57 | I13: 138.95 | J13: =AVERAGE(G13:I13) -> 138.1264 | L13: =AVERAGE(J13:K13) -> 138.1264 | M13: MSP K04/2023 | N13: KOSF/KPRL
A14: 10 | C14: E3 ENERGY | D14: MT PIS Polaris | E14: 44972 | F14: 44972 | G14: 134.536 | H14: 131.53 | I14: 133.5 | J14: =AVERAGE(G14:I14) -> 133.18867 | L14: =AVERAGE(J14:K14) -> 133.18867 | M14: S02/2023 AGO | N14: SOT
A15: 11 | C15: E3 ENERGY | D15: MT PIS Polaris | E15: 44968 | F15: 44970 | G15: 134.3216 | H15: 131.33 | I15: 133 | J15: =AVERAGE(G15:I15) -> 132.88387 | L15: =AVERAGE(J15:K15) -> 132.88387 | M15: S02/2023 PMS | N15: KOSF
A16: 12 | C16: E3 ENERGY | D16: MT Philoxenia | E16: 44989 | F16: 44988 | G16: 137.0016 | H16: 136.99 | I16: 137.75 | J16: =AVERAGE(G16:I16) -> 137.2472 | L16: =AVERAGE(J16:K16) -> 137.2472 | M16: AGO S03/2023 | N16: SOT
A17: 13 | C17: E3 ENERGY | D17: MT Philoxenia | E17: 44988 | F17: 44988 | G17: 137.0016 | H17: 136.99 | I17: 137.75 | J17: =AVERAGE(G17:I17) -> 137.2472 | L17: =AVERAGE(J17:K17) -> 137.2472 | M17: MSP S03/2023 | N17: KOSF
A18: 14 | C18: E3 ENERGY | D18: MT Philoxenia | E18: 44988 | F18: 44988 | G18: 137.0016 | H18: 136.99 | I18: 137.75 | J18: =AVERAGE(G18:I18) -> 137.2472 | L18: =AVERAGE(J18:K18) -> 137.2472 | M18: MSP S03/2023 | N18: SOT
C19: Average for the Month of February 2023 | G19: 133.98296 | H19: 133.87 | I19: 134.1 | J19: =AVERAGE(G19:I19) -> 133.98432 | L19: =AVERAGE(J19:K19) -> 133.98432

Sheet PMS Import
C3: PMS
C5: ='AGO Import'!C5 -> 44986
B7: Cargo No. | C7: Importer | D7: BL. Date | E7: Vessel | F7: ETA | G7: Qty Mt | H7: Vol. M3 | I7: CIF | J7: RDL & IDF | L7: Cost | Q7: Unit Cost | R7: RDL | S7: IDF
J8: RDL | K8: IDF | L8: USD a/c | O8: KES a/c | P8: Total KES | T8: Cost in USD | U8: Unit cost USD/Mt
I9: (USD/Mt) | J9: (USD/Mt) | K9: (USD/Mt) | L9: USD | M9: Exc Rate | N9: Amount Kes | Q9: (KES/Lts ) | R9: (KES/Lts ) | S9: (KES/Lts )
B10: 1 | C10: E3 ENERGY | D10: 22.02.2023 | E10: MT SANMAR SANGEET | F10: 02-04.03.2023 | G10: 37120.918 | H10: 51139.127 | I10: 838.06739 | J10: =(0.02*I10) -> 16.761348 | K10: =(0.035*I10) -> 29.332359 | L10: 31603214 | M10: ='[13]Exchange Rates '!L13 -> 138.1264 | N10: =L10*M10 -> 4.3652382e+09 | O10: 77167610 | P10: =N10+O10 -> 4.4424058e+09 | Q10: =P10/(H10*1000) -> 86.869019 | R10: =J10*G10*M10/(H10*1000) -> 1.6805484 | S10: =K10*G10*M10/(H10*1000) -> 2.9409597 | T10: =P10/M10 -> 32161888 | U10: =T10/G10 -> 866.40875 | V10: =((R10*H10)+(R11*H11)+(R12*H12)+(H13*R13)+(R14*H14)+(H15*R15))/H16 -> 1.7335008
B11: 2 | C11: E3 ENERGY | D11: 30.01.2023 | E11: MT PIS POLARIS | F11: 10-12.02.2023 | G11: 12444.22 | H11: 16692.116 | I11: 926.62403 | J11: =(0.02*I11) -> 18.532481 | K11: =(0.035*I11) -> 32.431841 | L11: 11706417 | M11: ='[13]Exchange Rates '!L15 -> 132.88387 | N11: =L11*M11 -> 1.555594e+09 | O11: 27601168 | P11: =N11+O11 -> 1.5831952e+09 | Q11: =P11/(H11*1000) -> 94.846883 | R11: =J11*G11*M11/(H11*1000) -> 1.8359553 | S11: =K11*G11*M11/(H11*1000) -> 3.2129217 | T11: =P11/M11 -> 11914126 | U11: =T11/G11 -> 957.40242 | V11: =((S11*H11)+(S10*H10)+(S12*H12)+(H13*S13)+(S14*H14)+(H15*S15))/H16 -> 3.0336263
B12: 3 | C12: E3 ENERGY | D12: 13.02.2023 | E12: MT PHILOXENIA-SOT | F12: 21-23.02.2023 | G12: 12156.891 | H12: 16418.796 | I12: 879.28148 | J12: =(0.02*I12) -> 17.58563 | K12: =(0.035*I12) -> 30.774852 | L12: 10789477 | M12: ='[13]Exchange Rates '!L17 -> 137.2472 | N12: =L12*M12 -> 1.4808255e+09 | O12: 25761157 | P12: =N12+O12 -> 1.5065867e+09 | Q12: =P12/(H12*1000) -> 91.759874 | R12: =J12*G12*M12/(H12*1000) -> 1.7870744 | S12: =K12*G12*M12/(H12*1000) -> 3.1273802 | T12: =P12/M12 -> 10977176 | U12: =T12/G12 -> 902.95914
B13: 4 | C13: E3 ENERGY | D13: 13.02.2023 | E13: MT PHILOXENIA-KOSF | F13: 21-23.02.2023 | G13: 3944.873 | H13: 5309.353 | I13: 879.28148 | J13: =(0.02*I13) -> 17.58563 | K13: =(0.035*I13) -> 30.774852 | L13: 3522375 | M13: ='[13]Exchange Rates '!L18 -> 137.2472 | N13: =L13*M13 -> 4.834361e+08 | O13: 8380381.7 | P13: =N13+O13 -> 4.9181649e+08 | Q13: =P13/(H13*1000) -> 92.632094 | R13: =J13*G13*M13/(H13*1000) -> 1.7932995 | S13: =K13*G13*M13/(H13*1000) -> 3.1382742 | T13: =P13/M13 -> 3583435.5 | U13: =T13/G13 -> 908.37791
B14: 5 | C14: GULF ENERGY | D14: 08.02.2023 | E14: MT FRONT VEGA | F14: 18-20.02.2023 | G14: 36402.328 | H14: 49941.457 | I14: 877.54717 | J14: =(0.02*I14) -> 17.550943 | K14: =(0.035*I14) -> 30.714151 | L14: 32440865 | M14: ='[13]Exchange Rates '!L11 -> 134.21307 | N14: =L14*M14 -> 4.353988e+09 | O14: 76792112 | P14: =N14+O14 -> 4.4307802e+09 | Q14: =P14/(H14*1000) -> 88.719481 | R14: =J14*G14*M14/(H14*1000) -> 1.716972 | S14: =K14*G14*M14/(H14*1000) -> 3.004701 | T14: =P14/M14 -> 33013031 | U14: =T14/G14 -> 906.8934
B15: 6 | C15: GULF ENERGY | D15: 09.02.2023 | E15: MT CLEAROCEAN MESQUITE | F15: 18-20.02.2023 | G15: 15332.924 | H15: 20556.675 | I15: 877.54717 | J15: =(0.02*I15) -> 17.550943 | K15: =(0.035*I15) -> 30.714151 | L15: 13663069 | M15: ='[13]Exchange Rates '!L12 -> 134.746 | N15: =L15*M15 -> 1.841044e+09 | O15: 32364552 | P15: =N15+O15 -> 1.8734085e+09 | Q15: =P15/(H15*1000) -> 91.133829 | R15: =J15*G15*M15/(H15*1000) -> 1.7639589 | S15: =K15*G15*M15/(H15*1000) -> 3.0869281 | T15: =P15/M15 -> 13903259 | U15: =T15/G15 -> 906.75848
G16: =SUM(G10:G15) -> 117402.15 | H16: =SUM(H10:H15) -> 160057.52 | R16: =V10 -> 1.7335008 | S16: =V11 -> 3.0336263 | T16: =SUM(T10:T15) -> 1.0555292e+08 | U16: =T16/G16 -> 899.07137
T17: =T16/H16 -> 659.46863

Sheet AGO Import
C3: AGO
C5: 44986
B7: Cargo No. | C7: Importer | D7: BL. Date | E7: Vessel | F7: ETA | G7: Qty Mt | H7: Vol. M3 | I7: CIF | J7: RDL & IDF | L7: Cost | Q7: Unit Cost | R7: RDL | S7: IDF | T7: COST
J8: RDL | K8: IDF | L8: USD a/c | O8: KES a/c | P8: Total KES
I9: (USD/Mt) | J9: (USD/Mt) | K9: (USD/Mt) | L9: USD | M9: Exc Rate | N9: Amount Kes | Q9: (KES/Lts ) | R9: (KES/Lts ) | S9: (KES/Lts ) | T9: USD | U9: Unit cost USD/Mt
B10: 1 | C10: TEXAS | D10: 02.02.2023 | E10: MT SEALEGEND | F10: 11-13.02.2023 | G10: 50542.573 | H10: 61592.22 | I10: 926.61961 | J10: =0.02*I10 -> 18.532392 | K10: =(0.035*I10) -> 32.431686 | L10: 47514086 | M10: ='[13]Exchange Rates '!L5 -> 133.1196 | N10: =(L10*M10) -> 6.3250561e+09 | O10: 1.10019e+08 | P10: =N10+O10 -> 6.4350751e+09 | Q10: =P10/(H10*1000) -> 104.4787 | R10: =(J10*G10*M10)/(H10*1000) -> 2.0244403 | S10: =(K10*G10*M10)/(H10*1000) -> 3.5427705 | T10: =P10/M10 -> 48340554 | U10: =T10/G10 -> 956.43238 | V10: =((R10*H10)+(H11*R11)+(R12*H12)+(H13*R13)+(R14*H14)+(H15*R15))/H16 -> 1.9943291
B11: 2 | C11: ORYX ENERGIES | D11: 13.02.2023 | E11: MT STI LOTUS | F11: 23-25.02.2023 | G11: 51275.358 | H11: 61204.292 | I11: 856.01748 | J11: =0.02*I11 -> 17.12035 | K11: =(0.035*I11) -> 29.960612 | L11: 44544464 | M11: ='[13]Exchange Rates '!L6 -> 137.2472 | N11: =(L11*M11) -> 6.113603e+09 | O11: 1.0627843e+08 | P11: =N11+O11 -> 6.2198814e+09 | Q11: =P11/(H11*1000) -> 101.62492 | R11: =(J11*G11*M11)/(H11*1000) -> 1.9685341 | S11: =(K11*G11*M11)/(H11*1000) -> 3.4449347 | T11: =P11/M11 -> 45318822 | U11: =T11/G11 -> 883.83239 | V11: =((S10*H10)+(H11*S11)+(S12*H12)+(H13*S13)+(S14*H14)+(H15*S15))/H16 -> 3.490076
A12: VTTI | B12: 3 | C12: E3 ENERGY | D12: 08.02.2023 | E12: MT SERENGETI-VTTI | F12: 20-22.02.2023 | G12: 24198.865 | H12: 28949.991 | I12: 858.51517 | J12: =0.02*I12 -> 17.170303 | K12: =(0.035*I12) -> 30.048031 | L12: 20973536 | M12: ='[13]Exchange Rates '!L7 -> 135.62893 | N12: =(L12*M12) -> 2.8446183e+09 | O12: 50376060 | P12: =N12+O12 -> 2.8949943e+09 | Q12: =P12/(H12*1000) -> 99.999835 | R12: =(J12*G12*M12)/(H12*1000) -> 1.9466007 | S12: =(K12*G12*M12)/(H12*1000) -> 3.4065513 | T12: =P12/M12 -> 21344961 | U12: =T12/G12 -> 882.06456
A13: KOSF | B13: 4 | C13: E3 ENERGY | D13: 08.02.2023 | E13: MT SERENGETI-KOSF | F13: 20-22.02.2023 | G13: 16110.36 | H13: 19278.644 | I13: 858.51517 | J13: =0.02*I13 -> 17.170303 | K13: =(0.035*I13) -> 30.048031 | L13: 14036454 | M13: ='[13]Exchange Rates '!L8 -> 135.62893 | N13: =(L13*M13) -> 1.9037493e+09 | O13: 33551645 | P13: =N13+O13 -> 1.9373009e+09 | Q13: =P13/(H13*1000) -> 100.48948 | R13: =(J13*G13*M13)/(H13*1000) -> 1.9460728 | S13: =(K13*G13*M13)/(H13*1000) -> 3.4056274 | T13: =P13/M13 -> 14283832 | U13: =T13/G13 -> 886.62403
B14: 5 | C14: E3 ENERGY | D14: 02.02.2023 | E14: MT PIS POLARIS | F14: 10-12.02.2023 | G14: 14586.144 | H14: 17817.317 | I14: 953.99504 | J14: =0.02*I14 -> 19.079901 | K14: =(0.035*I14) -> 33.389826 | L14: 14045754 | M14: ='[13]Exchange Rates '!L14 -> 133.18867 | N14: =(L14*M14) -> 1.8707352e+09 | O14: 33067503 | P14: =N14+O14 -> 1.9038027e+09 | Q14: =P14/(H14*1000) -> 106.85126 | R14: =(J14*G14*M14)/(H14*1000) -> 2.0803747 | S14: =(K14*G14*M14)/(H14*1000) -> 3.6406558 | T14: =P14/M14 -> 14294030 | U14: =T14/G14 -> 979.97316
B15: 6 | C15: E3 ENERGY | D15: 11.02.2023 | E15: MT PHILOXENIA | F15: 21-23.02.2023 | G15: 16097.494 | H15: 19669.68 | I15: 899.1598 | J15: =0.02*I15 -> 17.983196 | K15: =(0.035*I15) -> 31.470593 | L15: 14610329 | M15: ='[13]Exchange Rates '!L16 -> 137.2472 | N15: =(L15*M15) -> 2.0052268e+09 | O15: 34656263 | P15: =N15+O15 -> 2.0398831e+09 | Q15: =P15/(H15*1000) -> 103.70698 | R15: =(J15*G15*M15)/(H15*1000) -> 2.0199069 | S15: =(K15*G15*M15)/(H15*1000) -> 3.534837 | T15: =P15/M15 -> 14862839 | U15: =T15/G15 -> 923.30143
G16: =SUM(G10:G15) -> 172810.79 | H16: =SUM(H10:H15) -> 208512.14 | R16: =V10 -> 1.9943291 | S16: =V11 -> 3.490076 | T16: =SUM(T10:T15) -> 1.5844504e+08 | U16: =T16/G16 -> 916.87003
T17: =T16/H16 -> 759.88398

Sheet DPK Import
C3: DPK
D5: ='AGO Import'!C5 -> 44986
B7: Cargo No. | C7: Importer | D7: BL. Date | E7: Vessel | F7: ETA | G7: Qty Mt | H7: Vol. M3 | I7: CIF | J7: RDL & IDF | L7: Cost | Q7: Unit Cost | R7: RDL | S7: IDF
J8: RDL | K8: IDF | L8: USD a/c | O8: KES a/c | P8: Total KES
J9: (USD/Mt) | K9: (USD/Mt) | L9: USD | M9: Exc Rate | N9: Amount Kes | Q9: (KES/Lts ) | R9: (KES/Lts ) | S9: (KES/Lts ) | T9: Cost in USD | U9: Unit cost USD/Mt
B10: 1 | C10: E3 ENERGY | D10: 03.02.2023 | E10: MT NAKHAL SILVER | F10: 12-14.02.2023 | G10: 28973.434 | H10: 36938.085 | I10: 982.38433 | J10: =(0.02*I10) -> 19.647687 | K10: =(0.035*I10) -> 34.383451 | L10: 28875611 | M10: ='[13]Exchange Rates '!L9 -> 133.90013 | N10: =(L10*M10) -> 3.8664482e+09 | O10: 67154307 | P10: =N10+O10 -> 3.9336025e+09 | Q10: =P10/(H10*1000) -> 106.49178 | R10: =(J10*G10*M10)/(H10*1000) -> 2.0635644 | S10: =(K10*G10*M10)/(H10*1000) -> 3.6112377 | T10: =P10/M10 -> 29377137 | U10: =T10/G10 -> 1013.9335 | V10: =((R10*H10)+(R11*H11))/H12 -> 2.0134756
B11: 2 | C11: ORYX ENERGIES | D11: 23.02.2023 | E11: MT HAFNIA LUPUS | F11: 03-05.03.2023 | G11: 27628.641 | H11: 35193.855 | I11: 900.22273 | J11: =(0.02*I11) -> 18.004455 | K11: =(0.035*I11) -> 31.507795 | L11: 25244161 | M11: ='[13]Exchange Rates '!J10 -> 138.73427 | N11: =(L11*M11) -> 3.5022302e+09 | O11: 60452268 | P11: =N11+O11 -> 3.5626825e+09 | Q11: =P11/(H11*1000) -> 101.23024 | R11: =(J11*G11*M11)/(H11*1000) -> 1.9609043 | S11: =(K11*G11*M11)/(H11*1000) -> 3.4315825 | T11: =P11/M11 -> 25679903 | U11: =T11/G11 -> 929.46674
G12: =SUM(G10:G11) -> 56602.075 | H12: =SUM(H10:H11) -> 72131.94 | R12: =V10 -> 2.0134756 | S12: =V12 -> 3.5235822 | T12: =SUM(T10:T11) -> 55057039 | U12: =T12/G12 -> 972.70355 | V12: =((S10*H10)+(S11*H11))/H12 -> 3.5235822
T13: =T12/H12 -> 763.28239

Sheet WEIGHTED AVERAGE COST
B2: WEIGHTED AVERAGE COST ( Cu) FOR THE MONTH OF FEBRUARY 2023(KES/L)
B4: Super Petrol (PMS)
B5: COLUMN | D5: A | E5: B | F5: C | G5: D | H5: E | I5: F | J5: G | K5: H | L5: I
B6: IMPORTS | C6: CARGO NAME | I6: RDL | J6: IDF | K6: (B+C+D+E+F+G) | L6: A*F
C7: PMS | D7: M3 | E7: Kes/lit | F7: Kes/lit | G7: Kes/lit | H7: Kes/lit | I7: Kes/lit | J7: Kes/lit | K7: Kes/lit | L7: KES '000'
B8: ='AGO Import'!C5 -> 44986
B9: ='PMS Import'!C10 -> E3 ENERGY | C9: ='PMS Import'!E10 -> MT SANMAR SANGEET | D9: ='PMS Import'!H10 -> 51139.127 | E9: ='PMS Import'!Q10 -> 86.869019 | F9: =32.415+6+0.13+1.025+5+1.03343 -> 45.60343 | G9: 0 | H9: 0 | I9: ='PMS Import'!R10 -> 1.6805484 | J9: ='PMS Import'!S10 -> 2.9409597 | K9: =SUM(E9:J9) -> 137.09396 | L9: =(K9*D9) -> 7010865.3 | M9: ='PMS Import'!M10 -> 138.1264
B10: ='PMS Import'!C11 -> E3 ENERGY | C10: ='PMS Import'!E11 -> MT PIS POLARIS | D10: ='PMS Import'!H11 -> 16692.116 | E10: ='PMS Import'!Q11 -> 94.846883 | F10: =32.415+6+0.13+1.025+5+1.03343 -> 45.60343 | G10: 0 | H10: 0 | I10: ='PMS Import'!R11 -> 1.8359553 | J10: ='PMS Import'!S11 -> 3.2129217 | K10: =SUM(E10:J10) -> 145.49919 | L10: =(K10*D10) -> 2428689.4 | M10: ='PMS Import'!M11 -> 132.88387
B11: ='PMS Import'!C12 -> E3 ENERGY | C11: ='PMS Import'!E12 -> MT PHILOXENIA-SOT | D11: ='PMS Import'!H12 -> 16418.796 | E11: ='PMS Import'!Q12 -> 91.759874 | F11: =32.415+6+0.13+1.025+5+1.03343 -> 45.60343 | G11: 0 | H11: 0 | I11: ='PMS Import'!R12 -> 1.7870744 | J11: ='PMS Import'!S12 -> 3.1273802 | K11: =SUM(E11:J11) -> 142.27776 | L11: =(K11*D11) -> 2336029.5 | M11: ='PMS Import'!M12 -> 137.2472
B12: ='PMS Import'!C13 -> E3 ENERGY | C12: ='PMS Import'!E13 -> MT PHILOXENIA-KOSF | D12: ='PMS Import'!H13 -> 5309.353 | E12: ='PMS Import'!Q13 -> 92.632094 | F12: =32.415+6+0.13+1.025+5+1.03343 -> 45.60343 | G12: 0 | H12: 0 | I12: ='PMS Import'!R13 -> 1.7932995 | J12: ='PMS Import'!S13 -> 3.1382742 | K12: =SUM(E12:J12) -> 143.1671 | L12: =(K12*D12) -> 760124.66 | M12: ='PMS Import'!M13 -> 137.2472
B13: ='PMS Import'!C14 -> GULF ENERGY | C13: ='PMS Import'!E14 -> MT FRONT VEGA | D13: ='PMS Import'!H14 -> 49941.457 | E13: ='PMS Import'!Q14 -> 88.719481 | F13: =32.415+6+0.13+1.025+5+1.03343 -> 45.60343 | G13: 0 | H13: 0 | I13: ='PMS Import'!R14 -> 1.716972 | J13: ='PMS Import'!S14 -> 3.004701 | K13: =SUM(E13:J13) -> 139.04458 | L13: =(K13*D13) -> 6944089.1 | M13: ='PMS Import'!M14 -> 134.21307
B14: ='PMS Import'!C15 -> GULF ENERGY | C14: ='PMS Import'!E15 -> MT CLEAROCEAN MESQUITE | D14: ='PMS Import'!H15 -> 20556.675 | E14: ='PMS Import'!Q15 -> 91.133829 | F14: =32.415+6+0.13+1.025+5+1.03343 -> 45.60343 | G14: 0 | H14: 0 | I14: ='PMS Import'!R15 -> 1.7639589 | J14: ='PMS Import'!S15 -> 3.0869281 | K14: =SUM(E14:J14) -> 141.58815 | L14: =(K14*D14) -> 2910581.5 | M14: ='PMS Import'!M15 -> 134.746
B15: Demurrage | C15: MT PIS POLARIS | L15: =N15*M10/1000 -> 4037.0366 | N15: 30380.186
B16: Demurrage | C16: MT FRONT VEGA | L16: =N16*M13/1000 -> 5586.4953 | N16: 41624.079
B17: Demurrage | C17: MT CLEAROCEAN MESQUITE | L17: =N17*M14/1000 -> 4093.5356 | N17: 30379.645
B18: Demurrage | C18: MT PHILOXENIA | L18: =N18*M12/1000 -> 12823.565 | N18: 93434.077
B19: Demurrage | C19: MT SANMAR SANGEET | L19: =N19*M9/1000 -> 8640.0581 | N19: 62551.823
B20: Additional Demurrage - PMS S01/2023 | C20: MT JAG PADMA | L20: =N20*M20/1000 -> 6392.6371 | M20: 130.4411 | N20: 49007.844
B21: Additional Demurrage - PMS K01/2023 | C21: MT PERSEUS STAR | L21: =N21*M21/1000 -> 6627.5169 | M21: 131.62343 | N21: 50352.105
B22: Additional Demurrage - PMS K20/2022 | C22: MT SLOANE SQUARE | L22: =N22*M22/1000 -> 33125.228 | M22: 124.97612 | N22: 265052.47
B23: Additional Demurrage - PMS K23/2022 | C23: MT TORM HILDE | L23: =N23*M23/1000 -> 7416.0811 | M23: 130.11507 | N23: 56996.328
B24: Additional Demurrage - PMS K03/2023 | C24: MT FRONT VEGA | L24: =N24*M24/1000 -> 4158.8354 | M24: =M13 -> 134.21307 | N24: 30986.814
B25: Additional Demurrage - PMS K03/2023 | C25: MT CLEAROCEAN MESQUITE | L25: =N25*M25/1000 -> 3929.7942 | M25: =M14 -> 134.746 | N25: 29164.459
B26: Additional Demurrage - PMS K02/2023 | C26: MT TORM HILDE | L26: =N26*M26/1000 -> 3376.1575 | M26: 131.83307 | N26: 25609.338
B27: OTS FINANCING INTEREST-PMS K20/2022 | C27: MT SLOANE SQUARE | L27: =N27*M27/1000 -> 39154.882 | M27: 124.97612 | N27: 313298.92
B28: OTS FINANCING INTEREST-PMS K22/2022 | C28: MT HAFNIA DESPINA | L28: =N28*M28/1000 -> 20770.953 | M28: 128.0003 | N28: 162272.69
D29: =SUM(D9:D14) -> 160057.52 | E29: =((D9*E9)+(D10*E10)+(D11*E11)+(D12*E12)+(D13*E13)+(D14*E14))/D29 -> 89.519021 | L29: =SUM(L9:L28) -> 22550512
M31: =SUM(L15:L28)/D29 -> 1.0004702 | N31: =SUM(L20:L28)/D29 -> 0.78066987
D33: A | E33: B | L33: I
B34: KPRL | C34: CARGO NAME | L34: A*H
B38: TOTAL COST (KES) | L38: =L37+L29 -> 22550512
B39: TOTAL VOLUME (Litres) | D39: =D29+D37 -> 160057.52 | E39: =((D29*E29)+(D37*E37))/D39 -> 89.519021 | L39: =D29+D37 -> 160057.52
L40: =L38/L39 -> 140.89005
B43: =B2 -> WEIGHTED AVERAGE COST ( Cu) FOR THE MONTH OF FEBRUARY 2023(KES/L)
B45: Automotive Diesel (AGO)
B46: COLUMN | D46: A | E46: B | F46: C | G46: D | H46: E | I46: F | J46: G | K46: H | L46: I
B47: IMPORTS | C47: CARGO NAME | I47: RDL | J47: IDF | K47: (B+C+D+E+F+G) | L47: A*F
D48: M3 | E48: Kes/lit | F48: Kes/lit | G48: Kes/lit | H48: Kes/lit | I48: Kes/lit | J48: Kes/lit | K48: Kes/lit | L48: KES '000'
B49: =B8 -> 44986
B50: ='AGO Import'!C10 -> TEXAS | C50: ='AGO Import'!E10 -> MT SEALEGEND | D50: ='AGO Import'!H10 -> 61592.22 | E50: ='AGO Import'!Q10 -> 104.4787 | F50: =22.825+6+0.13+0.531+5+0.53528 -> 35.02128 | G50: 0 | H50: 0 | I50: ='AGO Import'!R10 -> 2.0244403 | J50: ='AGO Import'!S10 -> 3.5427705 | K50: =SUM(E50:J50) -> 145.06719 | L50: =K50*D50 -> 8935010.4 | M50: ='AGO Import'!M10 -> 133.1196 | N50: AMOUNT (USD) | O50: TIME TAKEN | P50: TIME ALLOWED | Q50: JETTY
...

Sheet RMS Cargos
E3: RMS
G4: ='PMS Import'!C5 -> 44986
B6: Cargo No. | C6: Importer | D6: BL. Date | E6: Vessel | F6: ETA | G6: Qty Mt | H6: Vol. M3 | I6: Cost | N6: Unit Cost
I7: USD a/c | L7: KES a/c | M7: Total KES | N7: KES/Lts
I8: USD | J8: Exc Rate | K8: Amount Kes
K9: =I9*J9 -> 0 | M9: =K9+L9 -> 0
K10: =I10*J10 -> 0 | M10: =K10+L10 -> 0
K11: =I11*J11 -> 0 | M11: =K11+L11 -> 0

Sheet PMS SUMMARY
B3: SUPER PETROL | D3: ='PMS Import'!E10 -> MT SANMAR SANGEET | E3: ='PMS Import'!E11 -> MT PIS POLARIS | F3: ='PMS Import'!E12 -> MT PHILOXENIA-SOT | G3: ='PMS Import'!E13 -> MT PHILOXENIA-KOSF | H3: ='PMS Import'!E14 -> MT FRONT VEGA | I3: ='PMS Import'!E15 -> MT CLEAROCEAN MESQUITE
D4: ='PMS Import'!C10 -> E3 ENERGY | E4: ='PMS Import'!C11 -> E3 ENERGY | F4: ='PMS Import'!C12 -> E3 ENERGY | G4: ='PMS Import'!C13 -> E3 ENERGY | H4: ='PMS Import'!C14 -> GULF ENERGY | I4: ='PMS Import'!C15 -> GULF ENERGY
B5: Costs paid in USD | D5: USD/MT | E5: USD/MT | F5: USD/MT | G5: USD/MT | H5: USD/MT | I5: USD/MT
B6: Free On Board (FOB) | C6: Platts based | D6: 830.8875 | E6: 837.119 | F6: 830.8875 | G6: 830.8875 | H6: 830.888 | I6: 830.888 | J6: =AVERAGE(D6:G6) -> 832.44538
B7: Freight & Premium (F&P) | C7: Varies as per Tender | D7: 4.86 | E7: 86.94 | F7: 45.96 | G7: 45.96 | H7: 44.23 | I7: 44.23 | J7: =AVERAGE(D7:G7) -> 45.93 | K7: 932.70175
B8: Letter of Credit Charges (LC) | C8: [1.20%*C&F] | D8: 10.02897 | E8: 11.088708 | F8: 10.52217 | G8: 10.52217 | H8: 10.501416 | I8: 10.501416 | J8: =AVERAGE(D8:G8) -> 10.540505 | K8: =J6+J7 -> 878.37537
B9: Certificate of Confomity (COC) | D9: 0.031654007 | E9: 0.16468638 | F9: 0.11263009 | G9: 0.11263009 | H9: 0.030290489 | I9: 0.077579334 | K9: =K7-K8 -> 54.326375
B10: Total USD based Cost | D10: =SUM(D6:D9) -> 845.80812 | E10: =SUM(E6:E9) -> 935.31239 | F10: =SUM(F6:F9) -> 887.4823 | G10: =SUM(G6:G9) -> 887.4823 | H10: =SUM(H6:H9) -> 885.64971 | I10: =SUM(I6:I9) -> 885.697
B11: Costs paid in KShs | D11: KSHS/MT | E11: KSHS/MT | F11: KSHS/MT | G11: KSHS/MT | H11: KSHS/MT | I11: KSHS/MT | K11: =K9*J22/(J23*1000) -> 5.4723563
B12: Insurance | C12: [1.003*C&F*0.0770%] | D12: 282.90053 | E12: 310.48382 | F12: 292.20943 | G12: 292.20943 | H12: 290.97674 | I12: 290.97674
B13: War Risk | C13: [1.003*C&F*0.0275%] | D13: 31.212415 | E13: 34.25568 | F13: 32.239466 | G13: 32.239466 | H13: 32.103463 | I13: 32.103463
B14: KPA Wharfage | C14: [USD 2.20/MT + 16% VAT] | D14: 345.5408 | E14: 342.9888 | F14: 340.1816 | G14: 340.1816 | H14: 339.416 | I14: 339.416
B15: Stevedoring Charges | C15: [USD 1.65/MT] | D15: 223.41 | E15: 221.76 | F15: 219.945 | G15: 219.945 | H15: 219.45 | I15: 219.45
B16: Ocean Losses | C16: [0.50%*CIFLW] | D16: 577.00599 | E16: 632.9667 | F16: 595.85476 | G16: 595.85476 | H16: 593.34664 | I16: 593.34664
B17: Adminstration Fees | C17: [0.5% of CIF] | D17: 567.37162 | E17: 622.69135 | F17: 586.0411 | G17: 586.0411 | H17: 583.56887 | I17: 583.56887
B18: Inspection Charges | D18: 10.048048 | E18: 10.419296 | F18: 10.434292 | G18: 11.252 | H18: 10.052396 | I18: 10.314623
B19: Merchant Shipping Fee | C19: [USD 0.3/MT] | D19: 40.62 | E19: 40.32 | F19: 39.99 | G19: 39.99 | H19: 39.9 | I19: 39.9
B20: Analysis +Recertification Charges | C20: ='[14]DPK CRYSTAL'!B37 -> [0.50%*CIF] | D20: 0.70799901 | E20: 2.1057487 | F20: 2.1622078 | G20: 6.6593139 | H20: 0.72437042 | I20: 1.7116545
B21: Total Kshs based costs (KShs/MT) | D21: =SUM(D12:D20) -> 2078.8174 | E21: =SUM(E12:E20) -> 2217.9914 | F21: =SUM(F12:F20) -> 2119.0579 | G21: =SUM(G12:G20) -> 2124.3727 | H21: =SUM(H12:H20) -> 2109.5385 | I21: =SUM(I12:I20) -> 2110.788
B22: Exchange rate (USD/KShs) | D22: ='PMS Import'!M10 -> 138.1264 | E22: ='PMS Import'!M11 -> 132.88387 | F22: ='PMS Import'!M12 -> 137.2472 | G22: ='PMS Import'!M13 -> 137.2472 | H22: ='PMS Import'!M14 -> 134.21307 | I22: ='PMS Import'!M15 -> 134.746 | J22: =AVERAGE(D22:G22) -> 136.37617
B23: Conversion factor (M3/MT) | D23: ='PMS Import'!H10/'PMS Import'!G10 -> 1.3776364 | E23: ='PMS Import'!H11/'PMS Import'!G11 -> 1.3413549 | F23: ='PMS Import'!H12/'PMS Import'!G12 -> 1.3505752 | G23: ='PMS Import'!H13/'PMS Import'!G13 -> 1.3458869 | H23: ='PMS Import'!H14/'PMS Import'!G14 -> 1.3719303 | I23: ='PMS Import'!H15/'PMS Import'!G15 -> 1.3406885 | J23: =AVERAGE(D23:G23) -> 1.3538634 | K23: =J8*J22/(J23*1000) -> 1.0617568
B24: USD based Cost coverted to KShs/Litre | D24: =(D10*D22)/(D23*1000) -> 84.803532 | E24: =(E10*E22)/(E23*1000) -> 92.658493 | F24: =(F10*F22)/(F23*1000) -> 90.187097 | G24: =(G10*G22)/(G23*1000) -> 90.501259 | H24: =(H10*H22)/(H23*1000) -> 86.641255 | I24: =(I10*I22)/(I23*1000) -> 89.017044
B25: Kshs based cost converted KShs/Litre | D25: =D21/(D23*1000) -> 1.5089739 | E25: =E21/(E23*1000) -> 1.6535455 | F25: =F21/(F23*1000) -> 1.5690039 | G25: =G21/(G23*1000) -> 1.5784184 | H25: =H21/(H23*1000) -> 1.5376426 | I25: =I21/(I23*1000) -> 1.574406
B26: Kipevu shore handling charges | C26: [0.19USD*16%VAT] | D26: =(0.19*1.16*D22)/1000 -> 0.030443059 | E26: =(0.19*1.16*E22)/1000 -> 0.029287604 | F26: =(0*1.16*F22)/1000 -> 0 | G26: =(0.19*1.16*G22)/1000 -> 0.030249283 | H26: =(0.19*1.16*H22)/1000 -> 0.02958056 | I26: =(0.19*1.16*I22)/1000 -> 0.029698018
B27: KPRL hospitality Charges/Storage | C27: [3.28USD*16%VAT] | D27: =(3.28*1.16*D22)/1000 -> 0.52554333 | E27: =(3.28*1.16*E22)/1000 -> 0.50559654 | F27: =(0*1.16*F22)/1000 -> 0 | G27: =(3.28*1.16*G22)/1000 -> 0.52219815 | H27: =(3.28*1.16*H22)/1000 -> 0.51065388 | I27: =(3.28*1.16*I22)/1000 -> 0.51268158
B28: Direct Order charges | C28: ; | D28: =(195*D22)/D34 -> 0.00052669354 | E28: =(0*E22)/E34 -> 0 | F28: =(455*F22)/F34 -> 0.0038034138 | G28: =(0*G22)/G34 -> 0 | H28: =(130*H22)/H34 -> 0.00034936303 | I28: =(0*I22)/I34 -> 0
B29: Escalation | C29: KShs. 0.2570/ Litre | D29: 0 | E29: 0
B30: RML | C30: KShs. 0.2699/ Litre | D30: 0 | E30: 0
B31: DI Collection charges | C31: KShs. 0.2105/ Litre | D31: 0 | E31: 0 | F31: 0 | G31: 0 | H31: 0 | I31: 0
B32: Import Declaration (IDF) Fees | D32: ='PMS Import'!$S10 -> 2.9409597 | E32: ='PMS Import'!$S11 -> 3.2129217 | F32: ='PMS Import'!$S12 -> 3.1273802 | G32: ='PMS Import'!$S13 -> 3.1382742 | H32: ='PMS Import'!$S14 -> 3.004701 | I32: ='PMS Import'!$S15 -> 3.0869281
B33: Unit Cargo cost in KShs/Litre | D33: =SUM(D24:D32) -> 89.809979 | E33: =SUM(E24:E32) -> 98.059844 | F33: =SUM(F24:F32) -> 94.887285 | G33: =SUM(G24:G32) -> 95.770399 | H33: =SUM(H24:H32) -> 91.724182 | I33: =SUM(I24:I32) -> 94.220757
B34: Product Volume in Litres | D34: =D36*1000 -> 51139127 | E34: =E36*1000 -> 16692116 | F34: =F36*1000 -> 16418796 | G34: =G36*1000 -> 5309353 | H34: =H36*1000 -> 49941457 | I34: =I36*1000 -> 20556675 | J34: =SUM(D34:I34) -> 160057524
B35: Weighted Average cost for all cargoes in KShs/Litre | J35: =((D33*D34)+(E33*E34)+(F33*F34)+(G33*G34)+(H33*H34)+(I33*I34))/J34 -> 92.552655
D36: ='PMS Import'!H10 -> 51139.127 | E36: ='PMS Import'!H11 -> 16692.116 | F36: ='PMS Import'!H12 -> 16418.796 | G36: ='PMS Import'!H13 -> 5309.353 | H36: ='PMS Import'!$H14 -> 49941.457 | I36: ='PMS Import'!$H15 -> 20556.675 | J36: ='WEIGHTED AVERAGE COST'!M31 -> 1.0004702
B37: Landed Cost KShs/Litre | J37: =SUM(J35:J36) -> 93.553125
C39: VAT factor | D39: 1.16 | E39: 1.16 | F39: 1.16 | G39: 1.16 | H39: 1.16 | I39: 1.16
C40: Applicable exchange rate | D40: =D$22 -> 138.1264 | E40: =E$22 -> 132.88387 | F40: =F$22 -> 137.2472 | G40: =G$22 -> 137.2472 | H40: =H$22 -> 134.21307 | I40: =I$22 -> 134.746
C41: Conversion factor | D41: =D$23 -> 1.3776364 | E41: =E$23 -> 1.3413549 | F41: =F$23 -> 1.3505752 | G41: =G$23 -> 1.3458869 | H41: =H$23 -> 1.3719303 | I41: =I$23 -> 1.3406885
C42: Product Volume | D42: =D$34 -> 51139127 | E42: =E$34 -> 16692116 | F42: =F$34 -> 16418796 | G42: =G$34 -> 5309353 | H42: =H$34 -> 49941457 | I42: =I$34 -> 20556675
B44: Weighted VAT charged costs | D44: =((D$42*D$50)+(E42*E50)+(F42*F50)+(G42*G50)+(H42*H50)+(I42*I50))/J34 -> 0.6458438
...

Sheet AGO SUMMARY
C3: DIESEL | E3: ='AGO Import'!E10 -> MT SEALEGEND | F3: ='AGO Import'!E11 -> MT STI LOTUS | G3: ='AGO Import'!E12 -> MT SERENGETI-VTTI | H3: ='AGO Import'!$E13 -> MT SERENGETI-KOSF | I3: ='AGO Import'!$E14 -> MT PIS POLARIS | J3: ='AGO Import'!$E15 -> MT PHILOXENIA
E4: ='AGO Import'!C10 -> TEXAS | F4: ='AGO Import'!C11 -> ORYX ENERGIES | G4: ='AGO Import'!C12 -> E3 ENERGY | H4: ='AGO Import'!$C13 -> E3 ENERGY | I4: ='AGO Import'!$C14 -> E3 ENERGY | J4: ='AGO Import'!$C15 -> E3 ENERGY
C5: Costs paid in USD | E5: USD/MT | F5: USD/MT | G5: USD/MT | H5: USD/MT | I5: USD/MT | J5: USD/MT
C6: Free On Board (FOB) | D6: Platts based | E6: 847.33459 | F6: 774.9379 | G6: 777.15868 | H6: 777.15868 | I6: 849.05424 | J6: 791.7308 | K6: =AVERAGE(E6:H6) -> 794.14746
C7: Freight & Premium (F&P) | D7: Varies as per Tender | E7: 76.72 | F7: 78.71 | G7: 78.98 | H7: 78.98 | I7: 102.3 | J7: 104.94 | K7: =AVERAGE(E7:H7) -> 78.3475
C8: Letter of Credit Charges | D8: [1.20%*C&F] | E8: 11.088655 | F8: 10.243775 | G8: 10.273664 | H8: 10.273664 | I8: 11.416251 | J8: 10.76005 | K8: =AVERAGE(E8:H8) -> 10.46994
C9: Certificate of Conformity (CoC) | E9: 0.030257275 | F9: 0.030087967 | G9: 0.03993257 | H9: 0.03993257 | I9: 0.1630838 | J9: 0.16786829
C10: Total USD based Cost | E10: =SUM(E6:E9) -> 935.17351 | F10: =SUM(F6:F9) -> 863.92176 | G10: =SUM(G6:G9) -> 866.45228 | H10: =SUM(H6:H9) -> 866.45228 | I10: =SUM(I6:I9) -> 962.93358 | J10: =SUM(J6:J9) -> 907.59871
C11: Costs paid in KShs | E11: KSHS/MT | F11: KSHS/MT | G11: KSHS/MT | H11: KSHS/MT | I11: KSHS/MT | J11: KSHS/MT
C12: Insurance | D12: [1.003*C&F*0.0770%] | E12: 304.93802 | F12: 283.83793 | G12: 285.2012 | H12: 285.2012 | I12: 319.89286 | J12: 298.81554
C13: War Risk | D13: [1.003*C&F*0.0275%] | E13: 33.643811 | F13: 31.315838 | G13: 31.466248 | H13: 31.466248 | I13: 35.29378 | J13: 32.968319
C14: KPA Wharfage | D14: [USD 2.20/MT + 16% VAT] | E14: 336.864 | F14: 339.416 | G14: 340.054 | H14: 340.054 | I14: 343.244 | J14: 340.1816
C15: Stevedoring Charges | D15: [USD 1.65/MT] | E15: 217.8 | F15: 219.45 | G15: 219.8625 | H15: 219.8625 | I15: 221.925 | J15: 219.945
C16: Ocean Losses | D16: [0.50%*CIFLW] | E16: 621.66077 | F16: 578.85806 | G16: 581.63014 | H16: 581.63014 | I16: 652.06494 | J16: 609.26221
C17: Adminstration Fees | D17: 0.5% of CIF | E17: 611.56894 | F17: 569.25162 | G17: 571.98573 | H17: 571.98573 | I17: 641.56166 | J17: 599.29
C18: Inspection Charges | E18: 9.9978595 | F18: 9.9957329 | G18: 10.147617 | H18: 10.291545 | I18: 10.338156 | J18: 10.292727
C19: Analysis +Recertification Charges | E19: 0.68585087 | F19: 0.67527093 | G19: 1.4308936 | H19: 2.1469341 | I19: 2.3788282 | J19: 2.1528181
C20: Merchant Shipping Fee | D20: USD 0.3/MT | E20: 39.6 | F20: 39.9 | G20: 39.975 | H20: 39.975 | I20: 40.35 | J20: 39.99
C21: Total Kshs based costs | E21: =SUM(E12:E20) -> 2176.7593 | F21: =SUM(F12:F20) -> 2072.7005 | G21: =SUM(G12:G20) -> 2081.7533 | H21: =SUM(H12:H20) -> 2082.6133 | I21: =SUM(I12:I20) -> 2267.0492 | J21: =SUM(J12:J20) -> 2152.8982
C22: Exchange rate (USD/KShs) | E22: ='AGO Import'!$M10 -> 133.1196 | F22: ='AGO Import'!$M11 -> 137.2472 | G22: ='AGO Import'!$M12 -> 135.62893 | H22: ='AGO Import'!$M13 -> 135.62893 | I22: ='AGO Import'!$M14 -> 133.18867 | J22: ='AGO Import'!$M15 -> 137.2472 | K22: =AVERAGE(E22:H22) -> 135.40617
C23: Conversion factor (M3/MT) | E23: ='AGO Import'!H10/'AGO Import'!G10 -> 1.2186206 | F23: ='AGO Import'!H11/'AGO Import'!G11 -> 1.1936395 | G23: ='AGO Import'!H12/'AGO Import'!G12 -> 1.1963367 | H23: ='AGO Import'!$H13/'AGO Import'!$G13 -> 1.1966613 | I23: ='AGO Import'!$H14/'AGO Import'!$G14 -> 1.2215235 | J23: ='AGO Import'!$H15/'AGO Import'!$G15 -> 1.2219094 | K23: =AVERAGE(E23:H23) -> 1.2013145 | L23: =K8*K22/(K23*1000) -> 1.1801192
C24: USD based Cost coverted to KShs/Litre | E24: =(E10*E22)/(E23*1000) -> 102.15643 | F24: =(F10*F22)/(F23*1000) -> 99.335557 | G24: =(G10*G22)/(G23*1000) -> 98.229867 | H24: =(H10*H22)/(H23*1000) -> 98.203226 | I24: =(I10*I22)/(I23*1000) -> 104.99335 | J24: =(J10*J22)/(J23*1000) -> 101.94322
C25: Kshs based cost converted KShs/Litre | E25: =E21/(E23*1000) -> 1.7862485 | F25: =F21/(F23*1000) -> 1.7364543 | G25: =G21/(G23*1000) -> 1.7401065 | H25: =H21/(H23*1000) -> 1.7403532 | I25: =I21/(I23*1000) -> 1.8559195 | J25: =J21/(J23*1000) -> 1.7619131
C26: Kipevu shore handling charges | D26: [0.19USD*16%VAT] | E26: =(0.19*1.16*E22)/1000 -> 0.02933956 | F26: =(0.19*1.16*F22)/1000 -> 0.030249283 | G26: =(0.19*1.16*G22)/1000 -> 0.029892617 | H26: =(0.19*1.16*H22)/1000 -> 0.029892617 | I26: =(0*1.16*I22)/1000 -> 0 | J26: =(0*1.16*J22)/1000 -> 0
C27: KPRL hospitality Charges | D27: [3.28USD*16%VAT] | E27: =(3.28*1.16*E22)/1000 -> 0.50649345 | F27: =(3.28*1.16*F22)/1000 -> 0.52219815 | G27: =(0*1.16*G22)/1000 -> 0 | H27: =(3.28*1.16*H22)/1000 -> 0.51604097 | I27: =(0*1.16*I22)/1000 -> 0 | J27: =(0*1.16*J22)/1000 -> 0
C28: Direct Order charges | E28: =(65*E22)/E35 -> 0.00014048485 | F28: =(195*F22)/F35 -> 0.00043727659 | G28: =(0*G22)/G35 -> 0 | H28: =(0*H22)/H35 -> 0 | I28: =(260*I22)/I35 -> 0.0019435616 | J28: =(260*J22)/J35 -> 0.0018141765
C29: Excise | D29: KShs. 0.0121/ Litre | E29: 0 | F29: 0
C30: RML | D30: KShs. 0.3621/ Litre | E30: 0 | F30: 0
C31: KOSF Charges Recovery | D31: KShs. 0.1643/ Litre | E31: 0 | F31: 0
C32: Excise Duty Recovery Charges | E32: 0 | F32: 0 | G32: 0 | H32: 0 | I32: 0 | J32: 0
C33: Import Declaration (IDF) Fees | E33: ='AGO Import'!$S10 -> 3.5427705 | F33: ='AGO Import'!$S11 -> 3.4449347 | G33: ='AGO Import'!$S12 -> 3.4065513 | H33: ='AGO Import'!$S13 -> 3.4056274 | I33: ='AGO Import'!$S14 -> 3.6406558 | J33: ='AGO Import'!$S15 -> 3.534837
C34: Unit Cargo cost in KShs/Litre | E34: =SUM(E24:E33) -> 108.02142 | F34: =SUM(F24:F33) -> 105.06983 | G34: =SUM(G24:G33) -> 103.40642 | H34: =SUM(H24:H33) -> 103.89514 | I34: =SUM(I24:I33) -> 110.49187 | J34: =SUM(J24:J33) -> 107.24178
C35: Product Volume in Litres | E35: =E37*1000 -> 61592220 | F35: =F37*1000 -> 61204292 | G35: =G37*1000 -> 28949991 | H35: =H37*1000 -> 19278644 | I35: =I37*1000 -> 17817317 | J35: =J37*1000 -> 19669680 | K35: =SUM(E35:J35) -> 2.0851214e+08
C36: Weighted Average cost for all cargoes in KShs/Litre | K36: =((E34*E35)+(F34*F35)+(G34*G35)+(H34*H35)+(I34*I35)+(J34*J35))/K35 -> 106.27034
C37: Volume in M3 | E37: ='AGO Import'!H10 -> 61592.22 | F37: ='AGO Import'!H11 -> 61204.292 | G37: ='AGO Import'!H12 -> 28949.991 | H37: ='AGO Import'!$H13 -> 19278.644 | I37: ='AGO Import'!$H14 -> 17817.317 | J37: ='AGO Import'!$H15 -> 19669.68 | K37: ='WEIGHTED AVERAGE COST'!M66 -> 0.35637073
C38: Landed Cost KShs/Litre | K38: =SUM(K36:K37) -> 106.62671
D41: VAT factor | E41: 1.16 | F41: 1.16 | G41: 1.16 | H41: 1.16 | I41: 1.16 | J41: 1.16
D42: Applicable exchange rate | E42: =E$22 -> 133.1196 | F42: =F$22 -> 137.2472 | G42: =G$22 -> 135.62893 | H42: =H$22 -> 135.62893 | I42: =I$22 -> 133.18867 | J42: =J$22 -> 137.2472
D43: Conversion factor | E43: =E$23 -> 1.2186206 | F43: =F$23 -> 1.1936395 | G43: =G$23 -> 1.1963367 | H43: =H$23 -> 1.1966613 | I43: =I$23 -> 1.2215235 | J43: =J$23 -> 1.2219094
D44: Product Volume | E44: =E$35 -> 61592220 | F44: =F$35 -> 61204292 | G44: =G$35 -> 28949991 | H44: =H$35 -> 19278644 | I44: =I$35 -> 17817317 | J44: =J$35 -> 19669680
...

Sheet DPK SUMMARY
B3: KEROSENE | D3: KOSF | E3: KOSF
D4: ='DPK Import'!E10 -> MT NAKHAL SILVER | E4: ='DPK Import'!E11 -> MT HAFNIA LUPUS
D5: ='DPK Import'!C10 -> E3 ENERGY | E5: ='DPK Import'!C11 -> ORYX ENERGIES
B6: Costs paid in USD | D6: USD/MT | E6: USD/MT
B7: Free On Board (FOB) | C7: Platts based | D7: 882.04495 | E7: 821.18078 | F7: =AVERAGE(D7:E7) -> 851.61287
B8: Freight & Premium (F&P) | C8: Varies as per Tender | D8: 97.62 | E8: 76.55 | F8: =AVERAGE(D8:E8) -> 87.085
B9: Letter of Credit Charges | C9: [1.2%*C&F] | D9: 11.755979 | E9: 10.772769 | F9: =AVERAGE(D9:E9) -> 11.264374
B10: Certificate of Conformity Cost (CoC) | D10: 0.071118682 | E10: 0.064633753
B11: Total USD based Cost | D11: =SUM(D7:D10) -> 991.49204 | E11: =SUM(E7:E10) -> 908.56819
B12: Costs paid in KShs | D12: KSHS/MT | E12: KSHS/MT
B13: Insurance | C13: [1.003*C&F*0.0770%] | D13: 329.77971 | E13: 303.88187
B14: War Risk | C14: [1.003*C&F*0.0275%] | D14: 36.384596 | E14: 33.527287
B15: KPA Wharfage | C15: [USD 2.20/MT + 16% VAT] | D15: 343.6268 | E15: 345.5408
B16: Stevedoring Charges | C16: [USD 1.65/MT] | D16: 222.1725 | E16: 223.41
B17: Ocean Losses | C17: [0.1%*CIFLW] | D17: 672.13396 | E17: 619.58871
B18: Adminstration Fees | C18: [0.5% of CIF] | D18: 661.39025 | E18: 609.45079
B19: Inspection Charges | D19: 10.100381 | E19: 10.112441
B20: Analysis +Recertification Charges | D20: 40.395 | E20: 40.62
B21: Merchant Shipping Fee | C21: [USD 0.3/MT] | D21: 1.8060647 | E21: 1.8966746
B22: Total Kshs based costs (KShs/Litre) | D22: =SUM(D13:D21) -> 2317.7893 | E22: =SUM(E13:E21) -> 2188.0286
B23: Exchange rate (USD/KShs) | D23: ='DPK Import'!M10 -> 133.90013 | E23: ='DPK Import'!M11 -> 138.73427 | F23: =AVERAGE(D23:E23) -> 136.3172
B24: Conversion factor (M3/MT) | D24: ='DPK Import'!H10/'DPK Import'!G10 -> 1.274895 | E24: ='DPK Import'!H11/'DPK Import'!G11 -> 1.2738178 | F24: =AVERAGE(D24:E24) -> 1.2743564 | H24: =F9*F23/(F24*1000) -> 1.2049439
B25: USD based Cost coverted to KShs/Litre | D25: =(D11*D23)/(D24*1000) -> 104.13479 | E25: =(E11*E23)/(E24*1000) -> 98.954136
B26: Kshs based cost converted KShs/Litre | D26: =D22/(D24*1000) -> 1.8180237 | E26: =E22/(E24*1000) -> 1.7176935
B27: Kipevu shore handling charges | C27: [0.19USD*16%VAT] | D27: =(0.19*1.16*D$23)/1000 -> 0.029511589 | E27: =(0.19*1.16*E$23)/1000 -> 0.030577032
B28: KPRL hospitality Charges | C28: [3.28USD*16%VAT] | D28: =(3.28*1.16*D$23)/1000 -> 0.50946323 | E28: =(3.28*1.16*E$23)/1000 -> 0.52785614
B29: Direct Order charges | D29: =(0*D$23)/D$33 -> 0 | E29: =(0*E$23)/E$33 -> 0
B30: KOSF Charges Recovery | C30: [KShs 0.2974/ltr] | D30: 0 | E30: 0
B31: Import Declaration Fees | D31: ='DPK Import'!S10 -> 3.6112377 | E31: ='DPK Import'!S11 -> 3.4315825
B32: Unit Cargo cost in KShs/Litre | D32: =SUM(D25:D31) -> 110.10302 | E32: =SUM(E25:E31) -> 104.66185
B33: Product Volume in Litres | D33: =D35*1000 -> 36938085 | E33: =E35*1000 -> 35193855 | F33: =SUM(D33:E33) -> 72131940
B34: Weighted Average cost for all cargoes in KShs/Litre | F34: =((D32*D33)+(E32*E33))/F33 -> 107.44822
B35: Volume in M3 | D35: ='DPK Import'!H10 -> 36938.085 | E35: ='DPK Import'!H11 -> 35193.855 | F35: ='WEIGHTED AVERAGE COST'!M96 -> 1.5983377
B36: Landed Cost KShs/Litre | F36: =SUM(F34:F35) -> 109.04656
C38: VAT factor | D38: 1.16 | E38: 1.16
C39: Applicable exchange rate | D39: =D$23 -> 133.90013 | E39: =E$23 -> 138.73427
C40: Conversion factor | D40: =D$24 -> 1.274895 | E40: =E$24 -> 1.2738178
C41: Product Volume | D41: =D$33 -> 36938085 | E41: =E$33 -> 35193855
B43: Weighted VAT charged costs | D43: =((D41*D48)+(E41*E48))/F33 -> 0.74013888
B44: Weighted Non-VAT charged costs | D44: =F35+((D41*D58)+(E41*E58))/F33 -> 104.66296
...

Sheet VAT Breakdown for PMS_AGO_DPK
B2: Breakdown of the costs of Super Petrol (PMS), Diesel (AGO) and Kerosene (DPK) in Nairobi: 15th March - 14th April 2023
B3: Cost Item | C3: Cost Description | D3: Super Petrol | E3: Diesel | F3: Kerosene
D4: KShs/Litre | E4: KShs/Litre | F4: KShs/Litre
B5: Landed Cost (a) | C5: Weighted Average cost for all imports | D5: ='Nairobi_Price VAT Inclusive'!C6 -> 90.386689 | E5: ='Nairobi_Price VAT Inclusive'!E6 -> 103.01178 | F5: ='Nairobi_Price VAT Inclusive'!G6 -> 105.4031
B7: Pipeline Transport (Msa-Nrb) | C7: Pipeline (100% PMS, AGO & IK) | D7: ='Nairobi_Price VAT Inclusive'!C24 -> 2.5266 | E7: ='Nairobi_Price VAT Inclusive'!E24 -> 2.5266 | F7: ='Nairobi_Price VAT Inclusive'!G24 -> 2.5266
B8: Road Transport (Msa-Nrb) - Bridging | C8: Road (0% PMS, AGO & IK) | D8: 0 | E8: 0 | F8: 0
B9: Pipeline Losses | C9: Pipeline (0.25%) | D9: ='Nairobi_Price VAT Inclusive'!C26 -> 0.065748689 | E9: ='Nairobi_Price VAT Inclusive'!E26 -> 0.067033093 | F9: ='Nairobi_Price VAT Inclusive'!G26 -> 0.065837941
B10: Depot Losses | C10: 0.5% PMS; 0.3% For DPK & AGO | D10: ='Nairobi_Price VAT Inclusive'!C27 -> 0.70445024 | E10: ='Nairobi_Price VAT Inclusive'!E27 -> 0.43092702 | F10: ='Nairobi_Price VAT Inclusive'!G27 -> 0.42324391
B11: Delivery within 40kms of Nrb | C11: Delivery to retail stations | D11: ='Nairobi_Price VAT Inclusive'!C41 -> 0.53759193 | E11: ='Nairobi_Price VAT Inclusive'!E41 -> 0.53759193 | F11: ='Nairobi_Price VAT Inclusive'!G41 -> 0.53759193
B12: Storage and distribution (b) | D12: =SUM(D7:D11) -> 3.8343909 | E12: =SUM(E7:E11) -> 3.562152 | F12: =SUM(F7:F11) -> 3.5532738
B14: Importers Margin | C14: Wholesale | D14: ='Nairobi_Price VAT Inclusive'!C28 -> 4.204 | E14: ='Nairobi_Price VAT Inclusive'!E28 -> 4.174 | F14: ='Nairobi_Price VAT Inclusive'!G28 -> 4.174
B15: Dealers Margin | C15: Retail Investment &Operating Margin | D15: ='Nairobi_Price VAT Inclusive'!C42 -> 8.19 | E15: ='Nairobi_Price VAT Inclusive'!E42 -> 8.19 | F15: ='Nairobi_Price VAT Inclusive'!G42 -> 8.19
B17: Oil marketing companies margins (c ) | D17: =SUM(D14:D16) -> 12.394 | E17: =SUM(E14:E16) -> 12.364 | F17: =SUM(F14:F16) -> 12.364
B20: Excise Duty | C20: Tax | D20: 21.95302 | E20: 11.37099 | F20: 11.37098
B21: Road Maintenance Levy | C21: Levy | D21: 18 | E21: 18 | F21: 0
B22: Petroleum Development Levy | C22: Levy | D22: 5.4 | E22: 5.4 | F22: 0.4
B23: Petroleum Regulatory Levy | C23: Levy | D23: 0.25 | E23: 0.25 | F23: 0.25
B24: Railway Development Levy | C24: Levy | D24: ='PMS Import'!V10 -> 1.7335008 | E24: ='AGO Import'!V10 -> 1.9943291 | F24: ='DPK Import'!R12 -> 2.0134756
B25: Anti-adulteration Levy | C25: Levy | D25: 0 | E25: 0 | F25: 18
B26: Merchant Shipping Levy | C26: Levy | D26: ='PMS SUMMARY'!D46 -> 0.029475332 | E26: ='AGO SUMMARY'!E48 -> 0.033048548 | F26: ='DPK SUMMARY'!D45 -> 0.0014519287
B27: Import Declaration Fee | C27: Levy | D27: ='PMS SUMMARY'!D47 -> 3.0336263 | E27: ='AGO SUMMARY'!E49 -> 3.490076 | F27: ='DPK SUMMARY'!D46 -> 3.5235822 | G27: Actual last month(February-March 2023) | H27: 165.78712 | I27: 172.61363 | J27: 165.3549
B28: Value Added Tax (VAT) | C28: Tax | D28: 12.56 | E28: 12.76 | F28: 12.55
B29: Taxes and levies (d) | D29: =SUM(D20:D28) -> 62.959622 | E29: =SUM(E20:E28) -> 53.298444 | F29: =SUM(F20:F28) -> 48.10949
B30: Retail Prices in Nairobi (a) + (b) + (c ) + (d) | D30: =SUM(D5,D12,D17,D29) -> 169.5747 | E30: =SUM(E5,E12,E17,E29) -> 172.23638 | F30: =SUM(F5,F12,F17,F29) -> 169.42987 | H30: ='Nairobi_Price VAT Inclusive'!C49 -> 169.5747 | I30: ='Nairobi_Price VAT Inclusive'!E49 -> 172.23638 | J30: ='Nairobi_Price VAT Inclusive'!G49 -> 169.42987
D31: ='Nairobi_Price VAT Inclusive'!C48 -> + 12.56 | E31: ='Nairobi_Price VAT Inclusive'!E48 -> + 12.76 | F31: ='Nairobi_Price VAT Inclusive'!G48 -> + 12.55 | G31: Change from actual prices | H31: =H30-H27 -> 3.7875866 | I31: =I30-I27 -> -0.37725138 | J31: =J30-J27 -> 4.074965
B32: Summary | D32: Super Petrol | E32: Diesel | F32: Kerosene | G32: Published Prices (February-March 2023) | H32: =177.3 -> 177.3 | I32: 162 | J32: 145.94
D33: KShs/Litre | E33: KShs/Litre | F33: KShs/Litre | G33: Proposed Published Prices (March-April 2023) | H33: =177.3+2 -> 179.3 | I33: 162 | J33: 145.94
B34: Products Costs (a) | D34: =D5 -> 90.386689 | E34: =E5 -> 103.01178 | F34: =F5 -> 105.4031 | G34: Change from published prices | H34: =H30-H33 -> -9.725298 | I34: =I30-I33 -> 10.236378 | J34: =J30-J33 -> 23.489867
B35: Distribution and storage Costs (b) | D35: =D12 -> 3.8343909 | E35: =E12 -> 3.562152 | F35: =F12 -> 3.5532738
B36: Margins (c ) | D36: =D17 -> 12.394 | E36: =E17 -> 12.364 | F36: =F17 -> 12.364 | G36: Stabilization Delta | H36: =H30-H33 -> -9.725298 | I36: =I30-I33 -> 10.236378 | J36: =J30-J33 -> 23.489867
B37: Taxes & Levies (d) | D37: =D29 -> 62.959622 | E37: =E29 -> 53.298444 | F37: =F29 -> 48.10949
B38: Retail Prices in Nairobi | D38: =SUM(D34:D37) -> 169.5747 | E38: =SUM(E34:E37) -> 172.23638 | F38: =SUM(F34:F37) -> 169.42987
H39: =H36/1.08 -> -9.0049055 | I39: =I30-12.36 -> 159.87638 | J39: =12.36-J36 -> -11.129867
D40: =D30/1.08*0.08 -> 12.561089 | E40: =E30/1.08*0.08 -> 12.75825 | F40: =F30/1.08*0.08 -> 12.55036
I41: =I33-I39 -> 2.1236224 | J41: =J39/1.08 -> -10.305432
I43: =I41/1.08 -> 1.9663171

Sheet VAT Breakdown for PUBLICATION
B2: Breakdown of the costs of Super Petrol (PMS), Diesel (AGO) and Kerosene (DPK) in Nairobi: 15th April - 14th May 2020
B3: Cost Item | C3: Cost Description | D3: Super Petrol | E3: Diesel | F3: Kerosene
D4: KShs/Litre | E4: KShs/Litre | F4: KShs/Litre
B5: Landed Cost (a) | C5: Weighted Average cost for all imports | D5: 32.22 | E5: 45.41 | F5: 27.56
B7: Pipeline Transport (Msa-Nrb) | C7: Pipeline (100% PMS, AGO & IK) | D7: 2.28 | E7: 2.28 | F7: 2.28
B8: Road Transport (Msa-Nrb) - Bridging | C8: Road (0% PMS, AGO & IK) | D8: 0 | E8: 0 | F8: 0
B9: Pipeline Losses | C9: Pipeline (0.25%) | D9: 0 | E9: 0 | F9: 0
B10: Depot Losses | C10: 0.5% PMS; 0.3% For DPK & AGO | D10: 0.37 | E10: 0.23 | F10: 0.18
B11: Delivery within 40kms of Nrb | C11: Delivery to petrol stations | D11: 0.54 | E11: 0.54 | F11: 0.54
B12: Storage and distribution (b) | D12: =SUM(D7:D11) -> 3.19 | E12: =SUM(E7:E11) -> 3.05 | F12: =SUM(F7:F11) -> 3
B14: Importers Margin | C14: Wholesale | D14: 4.2 | E14: 4.17 | F14: 4.17
B15: Dealers Margin | C15: Retail Investment Margin | D15: 4.05 | E15: 4.05 | F15: 4.05
C16: Retail Operating Margin | D16: 4.14 | E16: 4.14 | F16: 4.14
B17: Oil marketing companies margins (c ) | D17: =SUM(D14:D16) -> 12.39 | E17: =SUM(E14:E16) -> 12.36 | F17: =SUM(F14:F16) -> 12.36
B20: Excise Duty | C20: Tax | D20: 20.92 | E20: 10.84 | F20: 10.84 | L20: =ROUND(K20,2) -> 0
B21: Road Maintenance Levy | C21: Levy | D21: 18 | E21: 18 | F21: 0 | L21: =ROUND(K21,2) -> 0
B22: Petroleum Development Levy | C22: Levy | D22: 0.4 | E22: 0.4 | F22: 0.4 | L22: =ROUND(K22,2) -> 0
B23: Petroleum Regulatory Levy | C23: Levy | D23: 0.25 | E23: 0.25 | F23: 0.25 | L23: =ROUND(K23,2) -> 0
B24: Railway Development Levy | C24: Levy | D24: 0.62 | E24: 0.86 | F24: 0.52 | L24: =ROUND(K24,2) -> 0
B25: Anti-adulteration Levy | C25: Levy | D25: 0 | E25: 0 | F25: 18 | L25: =ROUND(K25,2) -> 0
B26: Merchant Shipping Levy | C26: Levy | D26: 0.02 | E26: 0.03 | F26: 0.02 | L26: 0.03
B27: Import Declaration Fee | C27: Levy | D27: 1.07 | E27: 1.51 | F27: 0.91
B28: Value Added Tax (VAT) | C28: Tax | D28: 3.79 | E28: 4.85 | F28: 3.42 | L28: =ROUND(K28,2) -> 0
B29: Taxes and levies (d) | D29: =SUM(D20:D28) -> 45.07 | E29: =SUM(E20:E28) -> 36.74 | F29: =SUM(F20:F28) -> 34.36 | L29: =SUM(L20:L28) -> 0.03
B30: Retail Prices in Nairobi (a) + (b) + (c ) + (d) | D30: =SUM(D5,D12,D17,D29) -> 92.87 | E30: =SUM(E5,E12,E17,E29) -> 97.56 | F30: =SUM(F5,F12,F17,F29) -> 77.28
B32: Summary | D32: Super Petrol | E32: Diesel | F32: Kerosene
D33: KShs/Litre | E33: KShs/Litre | F33: KShs/Litre
B34: Products Costs (a) | D34: =D5 -> 32.22 | E34: =E5 -> 45.41 | F34: =F5 -> 27.56
B35: Distribution and storage Costs (b) | D35: =D12 -> 3.19 | E35: =E12 -> 3.05 | F35: =F12 -> 3
B36: Margins (c ) | D36: =D17 -> 12.39 | E36: =E17 -> 12.36 | F36: =F17 -> 12.36
B37: Taxes & Levies (d) | D37: =D29 -> 45.07 | E37: =E29 -> 36.74 | F37: =F29 -> 34.36
B38: Retail Prices in Nairobi | D38: =SUM(D34:D37) -> 92.87 | E38: =SUM(E34:E37) -> 97.56 | F38: =SUM(F34:F37) -> 77.28
D41: =D34-D42 -> 31.22 | E41: =E34-E42 -> 45.05 | F41: =F34-F42 -> 25.96
D42: =ROUND('PMS SUMMARY'!J36,2) -> 1 | E42: =ROUND('AGO SUMMARY'!K37,2) -> 0.36 | F42: =ROUND('DPK SUMMARY'!F35,2) -> 1.6

Sheet Breakdown for PMS, AGO & DPK
B2: Breakdown of the costs of Super Petrol (PMS), Diesel (AGO) and Kerosene (DPK) in Nairobi: 15th Oct - 14th Nov 2020
B3: Cost Item | C3: Cost Description | D3: Super Petrol | E3: Diesel | F3: Kerosene
D4: KShs/Litre | E4: KShs/Litre | F4: KShs/Litre
B5: Landed Cost (a) | C5: Weighted Average cost for all imports | D5: ='PMS SUMMARY'!J37 -> 93.553125 | E5: ='AGO SUMMARY'!K38 -> 106.62671 | F5: ='DPK SUMMARY'!F36 -> 109.04656
B7: Pipeline Transport (Msa-Nrb) | C7: Pipeline (100% PMS, AGO & IK) | D7: =Nairobi!D9 -> 2.930856 | E7: =Nairobi!E9 -> 2.930856 | F7: =Nairobi!F9 -> 2.930856
B8: Road Transport (Msa-Nrb) - Bridging | C8: Road (0% PMS, AGO & IK) | D8: 0 | E8: 0 | F8: 0
B9: Pipeline Losses | C9: Pipeline (0.25%) | D9: =Nairobi!D13 -> 0.065748689 | E9: =Nairobi!E13 -> 0.067033093 | F9: =Nairobi!F13 -> 0.065837941
B10: Depot Losses | C10: 0.5% PMS; 0.3% For DPK & AGO | D10: =Nairobi!D15 -> 0.70445024 | E10: =Nairobi!E15 -> 0.43092702 | F10: =Nairobi!F15 -> 0.42324391
B11: Delivery within 40kms of Nrb | C11: Delivery to petrol stations | D11: =Nairobi!D23 -> 0.62360664 | E11: =Nairobi!E23 -> 0.62360664 | F11: =Nairobi!F23 -> 0.62360664
B12: Storage and distribution (b) | D12: =SUM(D7:D11) -> 4.3246616 | E12: =SUM(E7:E11) -> 4.0524228 | F12: =SUM(F7:F11) -> 4.0435445
B14: Importers Margin | C14: Wholesale | D14: =Nairobi!D17 -> 4.204 | E14: =Nairobi!E17 -> 4.174 | F14: =Nairobi!F17 -> 4.174
B15: Dealers Margin | C15: Retail | D15: =Nairobi!D21 -> 8.19 | E15: =Nairobi!E21 -> 8.19 | F15: =Nairobi!F21 -> 8.19
B16: Oil marketing companies margins (c ) | D16: =SUM(D14:D15) -> 12.394 | E16: =SUM(E14:E15) -> 12.364 | F16: =SUM(F14:F15) -> 12.364
B19: Excise Duty | C19: Tax | D19: 21.95302 | E19: 11.37099 | F19: 11.37098
B20: Road Maintenance Levy | C20: Levy | D20: 18 | E20: 18 | F20: 0
B21: Petroleum Development Levy | C21: Levy | D21: 5.4 | E21: 5.4 | F21: 0.4
B22: Petroleum Regulatory Levy | C22: Levy | D22: 0.25 | E22: 0.25 | F22: 0.25
B23: Railway Development Levy | C23: Levy | D23: ='PMS Import'!V10 -> 1.7335008 | E23: ='AGO Import'!V10 -> 1.9943291 | F23: ='DPK Import'!R12 -> 2.0134756
B24: Anti-adulteration Levy | C24: Levy | D24: 0 | E24: 0 | F24: 18 | H24: =H26-D26 -> 0.0004017929 | I24: =I26-E26 -> 0.00031339361
B25: Taxes and levies (d) | D25: =SUM(D19:D24) -> 47.336521 | E25: =SUM(E19:E24) -> 37.015319 | F25: =SUM(F19:F24) -> 32.034456
B26: Retail Prices in Nairobi (a) + (b) + (c ) + (d) | D26: =SUM(D5,D12,D16,D25) -> 157.60831 | E26: =SUM(E5,E12,E16,E25) -> 160.05845 | F26: =SUM(F5,F12,F16,F25) -> 157.48856 | H26: =Nairobi!D25 -> 157.60871 | I26: =Nairobi!E25 -> 160.05876 | J26: =Nairobi!F25 -> 157.48885
B28: Summary | D28: Super Petrol | E28: Diesel | F28: Kerosene
D29: KShs/Litre | E29: KShs/Litre | F29: KShs/Litre
B30: Products Costs (a) | D30: =D5 -> 93.553125 | E30: =E5 -> 106.62671 | F30: =F5 -> 109.04656
B31: Distribution and storage Costs (b) | D31: =D12 -> 4.3246616 | E31: =E12 -> 4.0524228 | F31: =F12 -> 4.0435445
B32: Margins (c ) | D32: =D16 -> 12.394 | E32: =E16 -> 12.364 | F32: =F16 -> 12.364
B33: Taxes & Levies (d) | D33: =D25 -> 47.336521 | E33: =E25 -> 37.015319 | F33: =F25 -> 32.034456
B34: Retail Prices in Nairobi | D34: =SUM(D30:D33) -> 157.60831 | E34: =SUM(E30:E33) -> 160.05845 | F34: =SUM(F30:F33) -> 157.48856

Sheet Mombasa
C2: MOMBASA CITY
C3: Petroleum Costing
C4: March 15 - April 14, 2023
D6: PMS | E6: AGO | F6: DPK
C7: Kshs/lt | D7: ='WEIGHTED AVERAGE COST'!L40 -> 140.89005 | E7: ='WEIGHTED AVERAGE COST'!L76 -> 143.64234 | F7: ='WEIGHTED AVERAGE COST'!L104 -> 141.0813 | H7: Weighted average cost (KPRL + KOSF)
G8: 1.16 | H8: 16% VAT Inclusive
C9: Kshs/lt | D9: =$G$10*$G$9*$G$8 -> 0 | E9: =$G$10*$G$9*$G$8 -> 0 | F9: =$G$10*$G$9*$G$8 -> 0 | G9: 0 | H9: % transported through pipeline - Zero for Mombasa
G10: 0 | H10: Pipeline Rate
C11: Kshs/lt | D11: =$G$11*G12*$G$8 -> 0 | E11: =$G$11*G12*$G$8 -> 0 | F11: =$G$11*G12*$G$8 -> 0 | G11: =8.14*G14/1000 -> 0 | H11: Bridging Rate Kshs 0.00912 per litre x distance
G12: =1-G9 -> 1 | H12: % transported through road
C13: Kshs/lt | D13: =$G$13*D7 -> 0 | E13: =$G$13*E7 -> 0 | F13: =$G$13*F7 -> 0 | G13: 0 | H13: Allowed pipeline losses
G14: 0 | H14: Distance from Source Depot
C15: Kshs/lt | D15: =G15*D7 -> 0.70445024 | E15: =G16*E7 -> 0.43092702 | F15: =G16*F7 -> 0.42324391 | G15: 0.005 | H15: Allowed depot losses. 0.5% for PMS,RMS and 0.3% for AGO,DPK
G16: 0.003
C18: Kshs/lt | D18: =3.05+0.49+0.664 -> 4.204 | E18: =3.05+0.46+0.664 -> 4.174 | F18: =3.05+0.46+0.664 -> 4.174 | H18: Allowed oil marketing company's gross wholesale margin
C20: Kshs/lt | D20: =SUM(D7:D19) -> 145.7985 | E20: =SUM(E7:E19) -> 148.24727 | F20: =SUM(F7:F19) -> 145.67855 | H20: Maximum Wholesale price
C22: Kshs/lt | D22: =4.14+4.05 -> 8.19 | E22: =4.14+4.05 -> 8.19 | F22: =4.14+4.05 -> 8.19 | H22: Allowed retail dealers gross margin
C24: Kshs/lt | D24: =$G$24*G8 -> 0.62360664 | E24: =$G$24*G8 -> 0.62360664 | F24: =$G$24*G8 -> 0.62360664 | G24: ='Delivery =<40km-Sept 2013'!E24 -> 0.53759193 | H24: 40km radius-Delivery rate within town
C26: Kshs/lt | D26: =D20+D22+D24 -> 154.6121 | E26: =E20+E22+E24 -> 157.06087 | F26: =F20+F22+F24 -> 154.49215 | H26: Maximum retail pump price
B28: February 15 - March 14 2023 | C28: =C26 -> Kshs/lt | D28: 151.11143 | E28: 157.40392 | F28: 150.71042
B29: Change | C29: =C28 -> Kshs/lt | D29: =D26-D28 -> 3.5006772 | E29: =E26-E28 -> -0.34304023 | F29: =F26-F28 -> 3.7817338
B31: Change | C31: % | D31: =D29/D28*100 -> 2.3166198 | E31: =E29/E28*100 -> -0.21793628 | F31: =F29/F28*100 -> 2.5092716

Sheet MOMBASA_PRICE VAT Inclusive
B3: OMC WHOLE-SALE FUEL PRICE BREAK-DOWN INCLUDING VAT
B4: =Mombasa!C4 -> March 15 - April 14, 2023 | C4: Super petrol | E4: Diesel | G4: Kerosene
B5: Item | C5: COST/ PRICE | D5: (INPUT)/ OUTPUT | E5: COST/ PRICE | F5: (INPUT)/ OUTPUT | G5: COST/ PRICE | H5: (INPUT)/ OUTPUT
B6: Landed cost, exclusive of VAT (KShs/Litre) [a+b+c] | C6: =C$7+C$8 -> 90.386689 | E6: =E$7+E$8 -> 103.01178 | G6: =G$7+G$8 -> 105.4031
B7: (a) None VAT-charged costs (KShs/litre) | C7: ='PMS SUMMARY'!D45 -> 89.740845 | E7: ='AGO SUMMARY'!E47 -> 102.43802 | G7: ='DPK SUMMARY'!D44 -> 104.66296
B8: (b) VAT-charged costs (KShs/litre) | C8: ='PMS SUMMARY'!D44 -> 0.6458438 | E8: ='AGO SUMMARY'!E46 -> 0.5737644 | G8: ='DPK SUMMARY'!D43 -> 0.74013888
A9: I. | B9: VATable amount (KShs/Litre) | C9: =C$6 -> 90.386689 | E9: =E$6 -> 103.01178 | G9: =G$6 -> 105.4031
B10: INPUT VAT 2 (on I.) | D10: =-(C9*0.08) -> -7.2309351 | F10: =-(E9*0.08) -> -8.2409425 | H10: =-(G9*0.08) -> -8.4322483
A11: II. | B11: Levies
B12: Excise duty | C12: ='Breakdown for PMS, AGO & DPK'!D19 -> 21.95302 | E12: ='Breakdown for PMS, AGO & DPK'!E19 -> 11.37099 | G12: ='Breakdown for PMS, AGO & DPK'!F19 -> 11.37098
B13: Merchant Shipping Fee | C13: ='PMS SUMMARY'!D46 -> 0.029475332 | E13: ='AGO SUMMARY'!E48 -> 0.033048548 | G13: ='DPK SUMMARY'!D45 -> 0.0014519287
B14: Import Declaration Fee | C14: ='PMS SUMMARY'!D47 -> 3.0336263 | E14: ='AGO SUMMARY'!E49 -> 3.490076 | G14: ='DPK SUMMARY'!D46 -> 3.5235822
B15: Road Maintenance Levy | C15: ='Breakdown for PMS, AGO & DPK'!D20 -> 18 | E15: ='Breakdown for PMS, AGO & DPK'!E20 -> 18 | G15: 0
B16: Anti-adulteration Levy | C16: 0 | E16: 0 | G16: ='Breakdown for PMS, AGO & DPK'!F24 -> 18
B17: Petroleum Development Levy | C17: ='Breakdown for PMS, AGO & DPK'!D21 -> 5.4 | E17: ='Breakdown for PMS, AGO & DPK'!E21 -> 5.4 | G17: ='Breakdown for PMS, AGO & DPK'!F21 -> 0.4
B18: Petroleum Regulatory Levy | C18: ='Breakdown for PMS, AGO & DPK'!D22 -> 0.25 | E18: ='Breakdown for PMS, AGO & DPK'!E22 -> 0.25 | G18: ='Breakdown for PMS, AGO & DPK'!F22 -> 0.25
B19: Railway Development Levy | C19: ='Breakdown for PMS, AGO & DPK'!D23 -> 1.7335008 | E19: ='Breakdown for PMS, AGO & DPK'!E23 -> 1.9943291 | G19: ='Breakdown for PMS, AGO & DPK'!F23 -> 2.0134756
B20: Sub-total | C20: =SUM(C12:C19) -> 50.399622 | E20: =SUM(E12:E19) -> 40.538444 | G20: =SUM(G12:G19) -> 35.55949
A21: III. | B21: Storage and Distribution Costs (Variable/Litre) | C21: =SUM(C$22:C$23) -> 0.70445024 | E21: =SUM(E$22:E$23) -> 0.43092702 | G21: =SUM(G$22:G$23) -> 0.42324391
B22: Storage and Distribution Costs (with VAT) | C22: =SUM(C$24:C$25) -> 0 | E22: =SUM(E$24:E$25) -> 0 | G22: =SUM(G$24:G$25) -> 0
B23: Storage and Distribution Costs (without VAT) | C23: =C$26+C$27 -> 0.70445024 | E23: =E$26+E$27 -> 0.43092702 | G23: =G$26+G$27 -> 0.42324391
B24: Pipeline Transport (Msa) | C24: =Mombasa!D9 -> 0 | E24: =Mombasa!E9 -> 0 | G24: =Mombasa!F9 -> 0
B25: Road Transport (Msa) - Bridging | C25: =Mombasa!D11 -> 0 | E25: =Mombasa!E11 -> 0 | G25: =Mombasa!F11 -> 0
B26: Pipeline Losses | C26: =Mombasa!D13 -> 0 | E26: =Mombasa!E13 -> 0 | G26: =Mombasa!F13 -> 0
B27: Depot Losses | C27: =Mombasa!D15 -> 0.70445024 | E27: =Mombasa!E15 -> 0.43092702 | G27: =Mombasa!F15 -> 0.42324391
A28: IV. | B28: Oil Marketers Margin | C28: =Mombasa!D18 -> 4.204 | E28: =Mombasa!E18 -> 4.174 | G28: =Mombasa!F18 -> 4.174
B29: VATable price [(I)+(III)+(IV)] | C29: =C$9+C$20+C$22+C$23+C$28 -> 145.69476 | E29: =E$9+E$20+E$22+E$23+E$28 -> 148.15515 | G29: =G$9+G$20+G$22+G$23+G$28 -> 145.55984
B30: Output VAT | D30: =CONCATENATE("+ ",ROUND((C$29*0.08),2)) -> + 11.66 | F30: =CONCATENATE("+ ",ROUND((E$29*0.08),2)) -> + 11.85 | H30: =CONCATENATE("+ ",ROUND((G$29*0.08),2)) -> + 11.64
B31: OMC Wholesale price exclusive of VAT | C31: =C$9+C$20+C$21+C$28 -> 145.69476 | E31: =E$9+E$20+E$21+E$28 -> 148.15515 | G31: =G$9+G$20+G$21+G$28 -> 145.55984
B32: ADD: VAT at wholesale | C32: =D30 -> + 11.66 | E32: =F30 -> + 11.85 | G32: =H30 -> + 11.64
B33: Wholesale Price inxclusive of VAT | C33: =C31+C32 -> 157.35476 | D33: =+D10+D30 -> 4.4290649 | E33: =E31+E32 -> 160.00515 | F33: =F10+F30 -> 3.6090575 | G33: =G31+G32 -> 157.19984 | H33: =H10+H30 -> 3.2077517
B35: RETAIL FUEL COST BREAK-DOWN INCLUDING VAT
C36: =C4 -> Super petrol | E36: =E4 -> Diesel | G36: =G4 -> Kerosene
A37: V. | B37: Wholesale price inclusive of VAT | C37: =C33 -> 157.35476 | E37: =E33 -> 160.00515 | G37: =G33 -> 157.19984
B38: Input VAT on Product at retail | D38: =-C32 -> -11.66 | F38: =-E32 -> -11.85 | H38: =-G32 -> -11.64
A39: VI. | B39: Distribution Cost
B40: Delivery Within 40kms | C40: =Mombasa!G24 -> 0.53759193 | E40: =C40 -> 0.53759193 | G40: =E40 -> 0.53759193
B41: Subtotal | C41: =SUM(C40) -> 0.53759193 | E41: =SUM(E40) -> 0.53759193 | G41: =SUM(G40) -> 0.53759193
A42: VII. | B42: Retailer's Margin | C42: =Mombasa!D22 -> 8.19 | E42: =Mombasa!E22 -> 8.19 | G42: =Mombasa!F22 -> 8.19
B43: Retail price | C43: =C$37+C$42+C$41 -> 166.08235 | E43: =E$37+E$42+E$41 -> 168.73274 | G43: =G$37+G$42+G$41 -> 165.92743
...

Sheet Kilifi
C2: KILIFI TOWN
C3: Petroleum Costing
C4: =Mombasa!C4 -> March 15 - April 14, 2023
D6: PMS | E6: AGO | F6: DPK
C7: Kshs/lt | D7: ='WEIGHTED AVERAGE COST'!L40 -> 140.89005 | E7: ='WEIGHTED AVERAGE COST'!L76 -> 143.64234 | F7: ='WEIGHTED AVERAGE COST'!L104 -> 141.0813 | H7: Weighted average cost (KPRL + KOSF)
G8: =Mombasa!G8 -> 1.16 | H8: 16% VAT Inclusive
C9: Kshs/lt | D9: =$G$10*$G$9*$G$8 -> 0 | E9: =$G$10*$G$9*$G$8 -> 0 | F9: =$G$10*$G$9*$G$8 -> 0 | G9: 0 | H9: % transported through pipeline - Zero for Mombasa
G10: 0 | H10: Pipeline Rate
C11: Kshs/lt | D11: =$G$11*G12*$G$8 -> 0 | E11: =$G$11*G12*$G$8 -> 0 | F11: =$G$11*G12*$G$8 -> 0 | G11: =8.14*G14/1000 -> 0 | H11: Bridging Rate Kshs 0.0814 per litre x distance
G12: 0 | H12: % transported through road
C13: Kshs/lt | D13: =$G$13*D7 -> 0 | E13: =$G$13*E7 -> 0 | F13: =$G$13*F7 -> 0 | G13: 0 | H13: Allowed pipeline losses
G14: 0 | H14: Distance from Source Depot
C15: Kshs/lt | D15: =G15*D7 -> 0.70445024 | E15: =G16*E7 -> 0.43092702 | F15: =G16*F7 -> 0.42324391 | G15: 0.005 | H15: Allowed depot losses. 0.5% for PMS,RMS and 0.3% for AGO,DPK
G16: 0.003
C17: Kshs/lt | D17: =Mombasa!D18 -> 4.204 | E17: =Mombasa!E18 -> 4.174 | F17: =Mombasa!F18 -> 4.174 | H17: Allowed oil marketing company's gross wholesale margin
C19: Kshs/lt | D19: =SUM(D7:D18) -> 145.7985 | E19: =SUM(E7:E18) -> 148.24727 | F19: =SUM(F7:F18) -> 145.67855 | H19: Maximum Wholesale price
